Workbook

Sheet README
A1: MASTER FORMS LIST & DATA-ELEMENT REPETITION - ALL LABOUR CODE RULES/SCHEME INSTRUMENTS IN ONE (audit pass 1 applied)
A2: Instruments consolidated (all read in full text this project, V-HIGH):
A3: SS (Central) Rules 2026 [G.S.R. 344(E)] - 31 forms | OSH (Central) Rules 2026 [G.S.R. 345(E)] - 27 forms |
A4: IR (Central) Rules 2026 [G.S.R. 342(E)] - 15 forms | EPF Scheme 2026 [G.S.R. 525(E)] - 12 forms (9 field-mapped; I/III/IV pending)
A5: KNOWN GAP: Code on Wages (Central) Rules 2026 [G.S.R. 343(E)] - gazette not yet obtained; registers/wage-slip family expected;
A6: a Wage-Rules column is reserved in spirit and will be added on extraction. ESI monthly (MC) is a portal format, not a rules form,
A7: and is therefore excluded here (it lives in the dictionary's L4).
A9: COUNTING METHOD (read before quoting numbers):
A10: Element repetition = number of DISTINCT FILINGS asking that element, summed across instruments. Procedural clusters in the
A11: source matrices (e.g., 11 SS appeal forms) count as ONE filing. Counts are FORM-count, not FREQUENCY-WEIGHTED: a monthly
A12: form counts once here. Frequency weighting (form-count x cadence per year) is the next artifact (master matrix Step 2).
A13: Element codes are the shared vocabulary deliberately used across all four source workbooks; six identifiers new to the EPF
... A16: SUMMARY (computed)
A17: Forms in master list | B17: =COUNTA(Master_Forms_List!A2:A120) -> 89
A18: Distinct data elements | B18: =COUNTA(Element_Repetition!A2:A200) -> 120
A19: Elements asked in 10+ filings | B19: =COUNTIF(Element_Repetition!L2:L200,">=10") -> 6
A20: Elements asked in 4-9 filings | B20: =COUNTIFS(Element_Repetition!L2:L200,">=4",Element_Repetition!L2:L200,"<10") -> 20
A21: Elements asked 2-3 times | B21: =COUNTIFS(Element_Repetition!L2:L200,">=2",Element_Repetition!L2:L200,"<4") -> 42
A22: Elements asked exactly once | B22: =COUNTIF(Element_Repetition!L2:L200,1) -> 52

Sheet Master_Forms_List
A1: Form (as tagged) | B1: Instrument (code rule / scheme) | C1: Title | D1: Instrument type | E1: Recurrence
A2: Form-I | B2: SS Rules 2026 [G.S.R. 344(E)] | C2: Appeal under section 23 of the Code | D2: Appeal | E2: EXCEPTIONAL
A3: Form-II | B3: SS Rules 2026 [G.S.R. 344(E)] | C3: Receipt Slip | D3: Acknowledgment | E3: EXCEPTIONAL
A4: Form-III | B4: SS Rules 2026 [G.S.R. 344(E)] | C4: Nomination / Fresh Nomination / Modification of Nomination (Ch.V gratuity) | D4: Declaration | E4: ONE-TIME
A5: Form-IV | B5: SS Rules 2026 [G.S.R. 344(E)] | C5: Application for gratuity by an Employee/nominee/legal heir | D5: Application | E5: EVENT-RECURRING
A6: Form-V | B6: SS Rules 2026 [G.S.R. 344(E)] | C6: Notice for payment / rejecting claim of gratuity | D6: Notice | E6: EVENT-RECURRING
A7: Form-VI | B7: SS Rules 2026 [G.S.R. 344(E)] | C7: Application for Direction (Competent Authority, Ch.V) | D7: Application | E7: EXCEPTIONAL
A8: Form-VII | B8: SS Rules 2026 [G.S.R. 344(E)] | C8: Notice for Appearance / Summon | D8: Notice | E8: EXCEPTIONAL
A9: Form-VIII | B9: SS Rules 2026 [G.S.R. 344(E)] | C9: Notice for payment of gratuity as determined by Competent/Appellate Authority | D9: Notice | E9: EXCEPTIONAL
A10: Form-IX | B10: SS Rules 2026 [G.S.R. 344(E)] | C10: Application for Recovery of Gratuity | D10: Application | E10: EXCEPTIONAL
A11: Form-X | B11: SS Rules 2026 [G.S.R. 344(E)] | C11: Certificate of Medical Officer/Practitioner (confinement/miscarriage/MTP/tubectomy/delivery) | D11: Certificate | E11: EVENT-RECURRING
A12: Form-XI | B12: SS Rules 2026 [G.S.R. 344(E)] | C12: Notice of claim for maternity benefit and payment thereof (ss.62-63); Part I Notice, Part II | D12: Claim notice | E12: EVENT-RECURRING
... A90: LWF periodic return | B90: LWF return [standard template] | C90: STANDARD TEMPLATE (16 state acts vary): establishment identity, employee counts by class, employee+employer contribution, remittance | D90: Return | E90: CALENDAR-RECURRING (half-yearly/annual by state)

Sheet Element_Repetition
A1: Element code | B1: Description | C1: SS Rules | D1: OSH Rules | E1: IR Rules | F1: EPF Scheme | G1: TDS 138/130 | H1: ESI MC/RC | I1: PT std | J1: LWF std | K1: (Wage Rules: pending) | L1: TOTAL
A2: EST_NAME | B2: Name of establishment (and address where combined) | C2: 13 | D2: 10 | E2: 5 | F2: 6 | G2: 1 | H2: 0 | I2: 1 | J2: 1 | K2: - | L2: =SUM(C2:J2) -> 37 | M2: already held by government
A3: EMP_NAME | B3: Employee/woman/claimant name (individual-level) | C3: 6 | D3: 6 | E3: 1 | F3: 3 | G3: 2 | H3: 1 | I3: 0 | J3: 0 | K3: - | L3: =SUM(C3:J3) -> 19 | M3: already held by government
A4: LIN | B4: Labour Identification Number | C4: 4 | D4: 8 | E4: 2 | F4: 1 | G4: 0 | H4: 0 | I4: 0 | J4: 0 | K4: - | L4: =SUM(C4:J4) -> 15 | M4: already held by government
A5: EST_ADDRESS | B5: Establishment address decomposed (premise/sub-locality/district/state/PIN) | C5: 6 | D5: 5 | E5: 0 | F5: 2 | G5: 0 | H5: 0 | I5: 0 | J5: 1 | K5: - | L5: =SUM(C5:J5) -> 14 | M5: already held by government
A6: EMPLOYER_NAME | B6: Name of employer + address | C6: 5 | D6: 6 | E6: 0 | F6: 2 | G6: 0 | H6: 0 | I6: 0 | J6: 0 | K6: - | L6: =SUM(C6:J6) -> 13 | M6: already held by government
A7: WAGE_COMPONENTS | B7: Basic/DA/allowances/OT/deductions/net | C7: 0 | D7: 4 | E7: 1 | F7: 3 | G7: 2 | H7: 2 | I7: 1 | J7: 0 | K7: - | L7: =SUM(C7:J7) -> 13
A8: AUTHORISED_PERSON | B8: Authorised/indenting person: name, designation, contact | C8: 6 | D8: 0 | E8: 0 | F8: 2 | G8: 0 | H8: 0 | I8: 0 | J8: 0 | K8: - | L8: =SUM(C8:J8) -> 8
A9: EMP_DESIGNATION | B9: Post/designation/nature of work | C9: 3 | D9: 4 | E9: 1 | F9: 0 | G9: 0 | H9: 0 | I9: 0 | J9: 0 | K9: - | L9: =SUM(C9:J9) -> 8
A10: CONTRACTOR_LIST | B10: Contractors with LIN and labour engaged | C10: 1 | D10: 3 | E10: 0 | F10: 4 | G10: 0 | H10: 0 | I10: 0 | J10: 0 | K10: - | L10: =SUM(C10:J10) -> 8
A11: PAN | B11: PAN (establishment in I; employer PAN/TAN in XIII/XV headers; employee PAN in XIII) | C11: 0 | D11: 3 | E11: 0 | F11: 3 | G11: 2 | H11: 0 | I11: 0 | J11: 0 | K11: - | L11: =SUM(C11:J11) -> 8 | M11: already held by government
A12: REG_NO_UNDER_CODE | B12: Registration number under the Code | C12: 3 | D12: 3 | E12: 1 | F12: 0 | G12: 0 | H12: 0 | I12: 0 | J12: 0 | K12: - | L12: =SUM(C12:J12) -> 7
A13: UAN | B13: Universal Account Number | C13: 1 | D13: 2 | E13: 1 | F13: 3 | G13: 0 | H13: 0 | I13: 0 | J13: 0 | K13: - | L13: =SUM(C13:J13) -> 7 | M13: already held by government
A14: EMP_DOJ | B14: Date of appointment | C14: 2 | D14: 2 | E14: 1 | F14: 1 | G14: 1 | H14: 0 | I14: 0 | J14: 0 | K14: - | L14: =SUM(C14:J14) -> 7
A15: ATTENDANCE_DAYS | B15: Month-wise employed/laid-off days | C15: 1 | D15: 4 | E15: 0 | F15: 1 | G15: 0 | H15: 1 | I15: 0 | J15: 0 | K15: - | L15: =SUM(C15:J15) -> 7
A16: HEADCOUNT_MATRIX | B16: Headcount by skill x gender (max/avg or year-end) | C16: 2 | D16: 2 | E16: 0 | F16: 0 | G16: 0 | H16: 0 | I16: 1 | J16: 1 | K16: - | L16: =SUM(C16:J16) -> 6
A17: EPF_CODE | B17: EPF code number of establishment (scheme registration identifier) | C17: 0 | D17: 0 | E17: 0 | F17: 6 | G17: 0 | H17: 0 | I17: 0 | J17: 0 | K17: - | L17: =SUM(C17:J17) -> 6 | M17: already held by government
A18: ESIC_IP_NO | B18: ESIC Insurance Number | C18: 1 | D18: 2 | E18: 0 | F18: 0 | G18: 0 | H18: 2 | I18: 0 | J18: 0 | K18: - | L18: =SUM(C18:J18) -> 5
A19: CONTRIBUTION_PAID | B19: Payments, proofs, outstanding/excess | C19: 2 | D19: 0 | E19: 0 | F19: 1 | G19: 0 | H19: 1 | I19: 0 | J19: 1 | K19: - | L19: =SUM(C19:J19) -> 5
A20: EMPLOYER_CONTACT | B20: Employer email / telephone / mobile | C20: 3 | D20: 0 | E20: 1 | F20: 0 | G20: 0 | H20: 0 | I20: 0 | J20: 0 | K20: - | L20: =SUM(C20:J20) -> 4
A21: ENTITY_TYPE | B21: Type of entity / ownership / sector | C21: 2 | D21: 1 | E21: 1 | F21: 0 | G21: 0 | H21: 0 | I21: 0 | J21: 0 | K21: - | L21: =SUM(C21:J21) -> 4
A22: EMP_FATHER_SPOUSE | B22: Father's/spouse's/husband's name | C22: 2 | D22: 2 | E22: 0 | F22: 0 | G22: 0 | H22: 0 | I22: 0 | J22: 0 | K22: - | L22: =SUM(C22:J22) -> 4
A23: NOMINEE_DETAILS | B23: Nominee particulars | C23: 3 | D23: 1 | E23: 0 | F23: 0 | G23: 0 | H23: 0 | I23: 0 | J23: 0 | K23: - | L23: =SUM(C23:J23) -> 4
A24: SEPARATIONS | B24: Dismissals/retrenchments/layoffs with payments | C24: 1 | D24: 1 | E24: 2 | F24: 0 | G24: 0 | H24: 0 | I24: 0 | J24: 0 | K24: - | L24: =SUM(C24:J24) -> 4
A25: CONTRIBUTION_ASSESSED | B25: Contribution self-assessment (both bases) | C25: 2 | D25: 0 | E25: 0 | F25: 2 | G25: 0 | H25: 0 | I25: 0 | J25: 0 | K25: - | L25: =SUM(C25:J25) -> 4
A26: ESIGN | B26: e-sign / digital signature | C26: 0 | D26: 2 | E26: 0 | F26: 2 | G26: 0 | H26: 0 | I26: 0 | J26: 0 | K26: - | L26: =SUM(C26:J26) -> 4
A27: PAYMENT_REFS | B27: Challan/TRRN payment references | C27: 0 | D27: 0 | E27: 0 | F27: 1 | G27: 1 | H27: 0 | I27: 1 | J27: 1 | K27: - | L27: =SUM(C27:J27) -> 4
A28: RETURN_PERIOD | B28: Period of return | C28: 1 | D28: 0 | E28: 0 | F28: 0 | G28: 0 | H28: 0 | I28: 1 | J28: 1 | K28: - | L28: =SUM(C28:J28) -> 3
A29: EMP_DOB | B29: Date of birth | C29: 1 | D29: 1 | E29: 0 | F29: 1 | G29: 0 | H29: 0 | I29: 0 | J29: 0 | K29: - | L29: =SUM(C29:J29) -> 3
... A121: GROUP_COMPANIES | B121: Inter-connected companies / common-management entities | C121: 0 | D121: 0 | E121: 1 | F121: 0 | G121: 0 | H121: 0 | I121: 0 | J121: 0 | K121: - | L121: =SUM(C121:J121) -> 1
C122: =SUM(C2:C121) -> 143 | D122: =SUM(D2:D121) -> 106 | E122: =SUM(E2:E121) -> 37 | F122: =SUM(F2:F121) -> 54 | G122: =SUM(G2:G121) -> 14 | H122: =SUM(H2:H121) -> 8 | I122: =SUM(I2:I121) -> 7 | J122: =SUM(J2:J121) -> 7 | K122: =SUM(K2:K121) -> 0
B123: =COUNTA(B2:B121) -> 120 | C123: =SUM(C122:J122) -> 376 | D123: =120/C123 -> 0.31914894
D124: =1-D123 -> 0.68085106 | E124: >0.6

Sheet Frequency_Weighted
A1: Element | B1: Description | C1: ANNUAL government transmissions (calendar-recurring filings, full-stack TG establishment) | D1: + Event-recurring filings asking it (count of filing types - per-event floor) | E1: Reading note
A2: WAGE_COMPONENTS | B2: Basic/DA/allowances/OT/deductions/net | C2: 55 | D2: 1 | E2: the same wage facts: ECR 12 + contractor stmt 12 + ESI MC 12 + ESI RC 2 + 138 4 + PT 12 + LWF 1 + annual return 1 (+ employee-facing wage slips 12 and Form 130, counted separately)
A3: PAYMENT_REFS | C3: 41 | D3: 0 | E3: challan/TRRN legs incl. monthly TDS deposit
A4: EMP_NAME | B4: Employee/woman/claimant name (individual-level) | C4: 40 | D4: 7 | E4: one workforce's names, retransmitted monthly across three identity systems
A5: CONTRACTOR_LIST | B5: Contractors with LIN and labour engaged | C5: 38 | D5: 2
A6: EPF_CODE | C6: 36 | D6: 2
A7: EST_NAME | B7: Name of establishment (and address where combined) | C7: 35 | D7: 21 | E7: header duplication annualised - PT is the monthly driver
A8: TAX_DEDUCTED | C8: 28 | D8: 0
A9: CONTRIBUTION_ASSESSED | B9: Contribution self-assessment (both bases) | C9: 26 | D9: 0 | E9: employer-computed contribution columns (ESIC computes state-side - the asymmetry, annualised)
A10: ATTENDANCE_DAYS | B10: Month-wise employed/laid-off days | C10: 24 | D10: 1 | E10: the SAME attendance atom, opposite polarities: NCP (ECR) + days-paid (ESI MC)
A11: UAN | B11: Universal Account Number | C11: 24 | D11: 2 | E11: ECR + contractor statement - 24 identity transmissions/yr for contract-heavy establishments
A12: CONTRIBUTION_PAID | B12: Payments, proofs, outstanding/excess | C12: 17 | D12: 0
A13: HEADCOUNT_MATRIX | B13: Headcount by skill x gender (max/avg or year-end) | C13: 16 | D13: 0
A14: PAN | B14: PAN (establishment in I; employer PAN/TAN in XIII/XV headers; employee PAN in XIII) | C14: 16 | D14: 2
A15: EPF_ESI_CODES | B15: EPF code / ESI code / ECR numbers as cross-references | C15: 15 | D15: 0
A16: ESIC_IP_NO | B16: ESIC Insurance Number | C16: 14 | D16: 3
A17: RETURN_PERIOD | B17: Period of return | C17: 14 | D17: 0
A18: EMPLOYER_NAME | B18: Name of employer + address | C18: 14 | D18: 7
A19: CONTRACT_COMMERCIALS | C19: 12 | D19: 0
A20: PT_REG_NO | C20: 12 | D20: 0
A21: EXIT_CAUSE_DATE | B21: Cause and date of exit/disablement/death | C21: 12 | D21: 1
A22: GST_NO | C22: 12 | D22: 1
A23: LIN | B23: Labour Identification Number | C23: 7 | D23: 6
A24: EST_ADDRESS | B24: Establishment address decomposed (premise/sub-locality/district/state/PIN) | C24: 5 | D24: 7
A25: EMP_DECLARATIONS | C25: 4 | D25: 0
A26: TAN | C26: 4 | D26: 1
A27: EMP_DOJ | B27: Date of appointment | C27: 4 | D27: 2
A28: AUTHORISED_PERSON | B28: Authorised/indenting person: name, designation, contact | C28: 3 | D28: 5
A29: GEO_COORDINATES | B29: Geo co-ordinates of establishment | C29: 2 | D29: 0
A30: GIG_WORKER_COUNT | B30: Gig/platform workers engaged (1 Apr) | C30: 2 | D30: 0
A31: ANNUAL_TURNOVER | B31: Annual turnover (excl. central taxes) | C31: 2 | D31: 0
A32: EMPLOYER_CONTACT | B32: Employer email / telephone / mobile | C32: 2 | D32: 1
A33: NATURE_OF_BUSINESS | B33: Principal activity / economic activity | C33: 1 | D33: 1
A34: WELFARE_AMENITIES | B34: Canteen/creche/ambulance/safety committee/officers/QMP | C34: 1 | D34: 0
A35: CONSTRUCTION_NATURE | B35: Nature of construction work | C35: 1 | D35: 2
A36: CONSTRUCTION_COST | B36: Estimated/incurred cost (rate basis + CE certificate) | C36: 1 | D36: 1
A37: MANDAYS_LOST | B37: Man-days lost (strike/lockout/accident) | C37: 1 | D37: 0
A38: BRANCH_STRUCTURE | B38: Head office / branch particulars | C38: 1 | D38: 1
... A41: MINE_IDENTITY | B41: Mine-specific identity block | C41: 1 | D41: 0
A42: LWF_REG_NO | C42: 1 | D42: 0
...
